File: results.txt
Shear Rate, Viscosity, Pressure, Trans Temp, Rot Temp
0.01, 0.91419, 23.6968, 1.0027, 1.0015
0.03, 0.8923, 23.7113, 1.0039, 1.0011
0.001, 16.56568, 23.7085, 1.0038, 1.0055
0.003, 3.20563, 23.6994, 1.0041, 1.0026
0.07, 1.16076, 23.6967, 1.003, 1.0028
0.01, 0.12401, 23.6984, 1.0007, 1.0006
0.03, 0.55281, 23.6943, 1.007, 1.0058
0.001, -5.73661, 23.7048, 1.0023, 1.0092
0.003, 0.05109, 23.7018, 0.999, 1.0016
0.07, 1.31818, 23.7079, 1.0128, 1.0029